{
 "cells": [
  {
   "cell_type": "code",
   "execution_count": null,
   "metadata": {},
   "outputs": [
    {
     "ename": "",
     "evalue": "",
     "output_type": "error",
     "traceback": [
      "\u001b[1;31mFailed to start the Kernel. \n",
      "\u001b[1;31mTraceback (most recent call last):\n",
      "\u001b[1;31m  File \"/Users/khin/.vscode/extensions/ms-toolsai.jupyter-2022.7.1102252217/pythonFiles/vscode_datascience_helpers/jupyter_daemon.py\", line 158, in _start_notebook\n",
      "\u001b[1;31m    from notebook import notebookapp as app\n",
      "\u001b[1;31m  File \"/Users/khin/.pyenv/versions/3.10.1/lib/python3.10/site-packages/notebook/notebookapp.py\", line 59, in <module>\n",
      "\u001b[1;31m    from tornado import httpserver\n",
      "\u001b[1;31m  File \"/Users/khin/.pyenv/versions/3.10.1/lib/python3.10/site-packages/tornado/httpserver.py\", line 29, in <module>\n",
      "\u001b[1;31m    import ssl\n",
      "\u001b[1;31m  File \"/Users/khin/.pyenv/versions/3.10.1/lib/python3.10/ssl.py\", line 98, in <module>\n",
      "\u001b[1;31m    import _ssl             # if we can't import it, let the error propagate\n",
      "\u001b[1;31mImportError: dlopen(/Users/khin/.pyenv/versions/3.10.1/lib/python3.10/lib-dynload/_ssl.cpython-310-darwin.so, 0x0002): Library not loaded: /opt/homebrew/opt/openssl@1.1/lib/libssl.1.1.dylib\n",
      "\u001b[1;31m  Referenced from: <0EA04741-2A0C-3334-888F-0A6F7D0942FB> /Users/khin/.pyenv/versions/3.10.1/lib/python3.10/lib-dynload/_ssl.cpython-310-darwin.so\n",
      "\u001b[1;31m  Reason: tried: '/opt/homebrew/opt/openssl@1.1/lib/libssl.1.1.dylib' (no such file), '/System/Volumes/Preboot/Cryptexes/OS/opt/homebrew/opt/openssl@1.1/lib/libssl.1.1.dylib' (no such file), '/opt/homebrew/opt/openssl@1.1/lib/libssl.1.1.dylib' (no such file), '/usr/local/lib/libssl.1.1.dylib' (no such file), '/usr/lib/libssl.1.1.dylib' (no such file, not in dyld cache)\n",
      "\u001b[1;31m\n",
      "\u001b[1;31mDuring handling of the above exception, another exception occurred:\n",
      "\u001b[1;31m\n",
      "\u001b[1;31mTraceback (most recent call last):\n",
      "\u001b[1;31m  File \"/Users/khin/.vscode/extensions/ms-toolsai.jupyter-2022.7.1102252217/pythonFiles/vscode_datascience_helpers/daemon/daemon_python.py\", line 54, in _decorator\n",
      "\u001b[1;31m    return func(self, *args, **kwargs)\n",
      "\u001b[1;31m  File \"/Users/khin/.vscode/extensions/ms-toolsai.jupyter-2022.7.1102252217/pythonFiles/vscode_datascience_helpers/jupyter_daemon.py\", line 111, in m_exec_module_observable\n",
      "\u001b[1;31m    self._start_notebook(args, cwd, env)\n",
      "\u001b[1;31m  File \"/Users/khin/.vscode/extensions/ms-toolsai.jupyter-2022.7.1102252217/pythonFiles/vscode_datascience_helpers/jupyter_daemon.py\", line 160, in _start_notebook\n",
      "\u001b[1;31m    from notebook import app as app\n",
      "\u001b[1;31mImportError: cannot import name 'app' from 'notebook' (/Users/khin/.pyenv/versions/3.10.1/lib/python3.10/site-packages/notebook/__init__.py)\n",
      "\u001b[1;31m\n",
      "\u001b[1;31mFailed to run jupyter as observable with args notebook --no-browser --notebook-dir=\"/Users/khin/local/hse/1st_semester/python/hw_1\" --config=/var/folders/8x/py78bv316g35sfyx4zxjd9vm0000gn/T/5496c3bf-a434-4273-9b3f-129d96210686/jupyter_notebook_config.py --NotebookApp.iopub_data_rate_limit=10000000000.0. \n",
      "View Jupyter <a href='command:jupyter.viewOutput'>log</a> for further details."
     ]
    }
   ],
   "source": [
    "f = open('data/purchase_log.txt')"
   ]
  }
 ],
 "metadata": {
  "kernelspec": {
   "display_name": "Python 3.12.4 64-bit",
   "language": "python",
   "name": "python3"
  },
  "language_info": {
   "name": "python",
   "version": "3.12.4"
  },
  "orig_nbformat": 4,
  "vscode": {
   "interpreter": {
    "hash": "b0fa6594d8f4cbf19f97940f81e996739fb7646882a419484c72d19e05852a7e"
   }
  }
 },
 "nbformat": 4,
 "nbformat_minor": 2
}
